Workbook

Sheet Inicio
A1: Modelo de negocio · La Vela
A2: Veladora diseñada para durar, con cartucho retornable, distribuida en tiendas y misceláneas a través de distribuidores con rutas, más canales directos y línea premium. Modelo a 36 meses en pesos mexicanos. Versión 2 · octubre de 2026.
A4: Cómo se usa
A5: 1. En 'Supuestos', celda D5: elige 1 = Base (lo que platicamos) o 2 = Optimizado. Celda D6: volumen Conservador, Medio o Alto.
A6: 2. Cambia cualquier celda con marco. Todo se recalcula solo. Las de marco grueso son las que más mueven el resultado.
A7: 3. Lee 'Resumen'. Para negociar con el distribuidor usa 'Todos_ganan'. Para encontrar dinero usa 'Palancas' y 'Sensibilidad'.
A8: 4. Cuando tengas cotizaciones y pruebas reales, reemplaza los ESTIMADOS y marca el riesgo como Validado en 'Riesgos'.
A9: 5. En 'Supuestos', celda D184: elige 1 = repuesto con funda o 2 = cartucho retornable. La hoja 'Cartucho' explica la diferencia.
A11: Cómo se lee
A12: Marco delgado | B12: Dato que puedes cambiar.
A13: Marco grueso | B13: Selector o supuesto clave: lo que más mueve el resultado.
A14: Fondo negro | B14: Resultado clave, o encabezado de tabla.
A15: Sin marco | B15: Fórmula: no tocar.
A17: Hojas
A18: Resumen | B18: Resultados por año, capital, punto de equilibrio y comparación Base vs Optimizado.
A19: Supuestos | B19: Todos los datos editables con su fuente. Selectores de escenario.
A20: Costeo | B20: Costo por pieza de cada producto, de la cera a la caja.
A21: Cartucho | B21: NUEVA. El cartucho retornable: cuánto cuesta cada llenado, cuántos hay que comprar y qué cambia contra la funda.
A22: Cascada | B22: Quién gana qué en cada pieza, a dónde se va cada peso y economía de canales directos.
A23: Todos_ganan | B23: Lo que gana el cliente, la tienda, el distribuidor y nosotros.
A24: Distribuidor | B24: NUEVA. Cuánto gana un distribuidor según cuántas tiendas surte, y cómo se califica una solicitud.
A25: Volumen | B25: Tiendas, piezas y canales mes a mes.
A26: Resultados | B26: Estado de resultados mensual y anual.
A27: Flujo | B27: Flujo de efectivo, capital de trabajo, necesidad de capital y recuperación.
A28: Capex_Capacidad | B28: Equipo por nivel, costo de transformación propia y capacidad de planta.
A29: Palancas | B29: Cuánto dinero deja cada mejora de eficiencia, e ideas extra.
... A34: Fuentes | B34: De dónde salió cada dato.
A36: Página del modelo: https://vela.capitaltorreon.com/modelo
A37: Ing. Ricardo López Reyero · Torreón, Coahuila

Sheet Resumen
A1: Resumen ejecutivo
A2: ="Escenario activo: "&IF(sel_costos=1,"Base (lo que platicamos)","Optimizado")&" · Volumen: "&CHOOSE(sel_vol,"Conservador","Medio","Alto") -> Escenario activo: Optimizado · Volumen: Medio
A4: Resultados por año (MXN) | B4: Año 1 | C4: Año 2 | D4: Año 3
A5: Ingresos netos | B5: =Resultados!AM20 -> 5217946.7 | C5: =Resultados!AN20 -> 8243815.7 | D5: =Resultados!AO20 -> 8853273.4
A6: Utilidad bruta | B6: =Resultados!AM32 -> 2044748.3 | C6: =Resultados!AN32 -> 3138264.3 | D6: =Resultados!AO32 -> 3316068.3
A7: Margen bruto | B7: =Resultados!AM33 -> 0.39186837 | C7: =Resultados!AN33 -> 0.38068103 | D7: =Resultados!AO33 -> 0.37455844
A8: Contribución | B8: =Resultados!AM46 -> 1322202.8 | C8: =Resultados!AN46 -> 2298152 | D8: =Resultados!AO46 -> 2449576.8
A9: EBITDA | B9: =Resultados!AM63 -> -44797.2 | C9: =Resultados!AN63 -> 987151.95 | D9: =Resultados!AO63 -> 1138576.8
A10: Margen EBITDA | B10: =Resultados!AM64 -> -0.0085852161 | C10: =Resultados!AN64 -> 0.11974454 | D10: =Resultados!AO64 -> 0.12860518
A11: Utilidad neta | B11: =Resultados!AM70 -> -50222.2 | C11: =Resultados!AN70 -> 609125.05 | D11: =Resultados!AO70 -> 683146.1
A12: Velas producidas | B12: =SUMIF(Volumen!$C$6:$AL$6,1,Volumen!$C$43:$AL$43) -> 144686.55 | C12: =SUMIF(Volumen!$C$6:$AL$6,2,Volumen!$C$43:$AL$43) -> 237215.06 | D12: =SUMIF(Volumen!$C$6:$AL$6,3,Volumen!$C$43:$AL$43) -> 260077.46
A13: Tiendas activas al cierre del año | B13: =Volumen!N11 -> 500 | C13: =Volumen!Z11 -> 500 | D13: =Volumen!AL11 -> 500
A15: Dinero y riesgo | B15: Valor
A16: Necesidad máxima de capital (incluye caja mínima) | B16: =capital_max -> 762969.43
A17: Mes en que se recupera lo invertido | B17: =mes_recup -> 19
A18: Flujo acumulado al mes 36 | B18: =flujo_36 -> 498793.3
A19: Inversión en equipo en 36 meses | B19: =capex_n1+IF(mes_planta<=meses_horizonte,capex_n2,0) -> 10850
A20: Punto de equilibrio: piezas al mes en el canal distribuidor (los canales directos ya aportan) | B20: =IF(contrib_pieza<=0,"Cada pieza pierde: no hay equilibrio",IFERROR(MAX(0,fijos_mes_y2-(Resultados!AN46/12-B21*contrib_pieza))/contrib_pieza,0)) -> 5540.7485
A21: Piezas al mes promedio año 2 (canal distribuidor) | B21: =SUMIF(Volumen!$C$6:$AL$6,2,Volumen!$C$16:$AL$16)/12 -> 19052
A22: Margen de seguridad sobre el punto de equilibrio | B22: =IF(ISNUMBER(B20),IFERROR(1-B20/B21,0),"-") -> 0.70917759
A23: Primer mes en que se rebasa la planta nivel 2 | B23: =mes_n3 -> No rebasa en 36 meses
A24: Volumen mínimo para que convenga planta propia (pzas/mes) | B24: =pe_planta -> 47377.267
A26: Por pieza (canal distribuidor) | B26: Semanal | C26: Repuesto | D26: Temporada | E26: Personalizada
A27: Precio al público | B27: =Cascada!B5 -> 49 | C27: =Cascada!C5 -> 34 | D27: =Cascada!D5 -> 65 | E27: =Cascada!E5 -> 99
A28: La tienda gana | B28: =Cascada!B9 -> 13.23 | C28: =Cascada!C9 -> 9.18 | D28: =Cascada!D9 -> 17.55 | E28: =Cascada!E9 -> 26.73
A29: El distribuidor gana | B29: =Cascada!B11 -> 6.0809 | C29: =Cascada!C11 -> 4.2194 | D29: =Cascada!D11 -> 8.0665 | E29: =Cascada!E11 -> 12.2859
A30: Nosotros ganamos | B30: =Cascada!B14 -> 5.4288666 | C30: =Cascada!C14 -> 2.984375 | D30: =Cascada!D14 -> 12.568108 | E30: =Cascada!E14 -> 26.470246
A31: Nuestro margen | B31: =Cascada!B15 -> 0.21211439 | C31: =Cascada!C15 -> 0.16804729 | D31: =Cascada!D15 -> 0.37018054 | E31: =Cascada!E15 -> 0.51189374
A32: Costo por hora de luz para el cliente | B32: =Costeo!C32 -> 0.29166667 | C32: =Costeo!D32 -> 0.20238095 | D32: =Costeo!E32 -> 0.38690476 | E32: =Costeo!F32 -> 0.58928571
A34: Lo que platicamos vs optimizado | B34: Base | C34: Optimizado | D34: Diferencia
A35: Utilidad por Semanal | B35: =Cascada!B63 -> -4.3952053 | C35: =Cascada!C63 -> 5.4288666 | D35: =Cascada!D63 -> 9.8240719
A36: Utilidad por Repuesto | B36: =Cascada!B64 -> -3.7493729 | C36: =Cascada!C64 -> 2.984375 | D36: =Cascada!D64 -> 6.7337479
A37: Utilidad ponderada por pieza | B37: =Cascada!B67 -> -2.4506208 | C37: =Cascada!C67 -> 7.20903 | D37: =Cascada!D67 -> 9.6596508
A38: Nuestra parte del peso del cliente (Semanal) | B38: =Cascada!B68 -> -0.097671228 | C38: =Cascada!C68 -> 0.1107932 | D38: =Cascada!D68 -> 0.20846442
A39: Costo de la Semanal | B39: =Cascada!B58 -> 26.119343 | C39: =Cascada!C58 -> 20.165185 | D39: =Cascada!D58 -> -5.9541581
A40: Gramos de cera por pieza | B40: =Cascada!B50 -> 458.64 | C40: =Cascada!C50 -> 397.992 | D40: =Cascada!D50 -> -60.648
A42: Todos ganan (promedio mensual año 2) | B42: Valor
A43: Cada tienda gana al mes | B43: =tienda_mes -> 508.02539
A44: El distribuidor gana al mes | B44: =dist_mes -> 116751.76
A45: Nosotros: EBITDA al mes | B45: =ebitda_mes_y2 -> 82262.663
...

Sheet Supuestos
A1: Supuestos del modelo
A2: Marco delgado = dato que puedes cambiar · Marco grueso = selector o supuesto clave · La columna F (Activo) es la que usa todo el modelo. Todos los precios al público incluyen IVA; los costos de insumos son sin IVA.
A4: Clave | B4: Concepto | C4: Unidad | D4: Base | E4: Optimizado | F4: Activo | G4: Fuente / nota
A5: sel_costos | B5: ESCENARIO DE COSTOS Y PRECIOS (1 = Base: lo que platicamos · 2 = Optimizado) | C5: 1 / 2 | D5: 2 | F5: =IF(D5=1,"Base","Optimizado") -> Optimizado | G5: Cambia este número y todo el modelo se recalcula.
A6: sel_vol | B6: ESCENARIO DE VOLUMEN (1 = Conservador · 2 = Medio · 3 = Alto) | C6: 1 / 2 / 3 | D6: 2 | F6: =CHOOSE(D6,"Conservador","Medio","Alto") -> Medio | G6: Define tiendas activas y piezas por tienda (tabla al final de esta hoja).
A8: 1. GENERALES
A9: tc | B9: Tipo de cambio | C9: MXN por USD | D9: 18.37 | E9: 18.37 | F9: =IF(sel_costos=1,D9,E9) -> 18.37 | G9: DOF del 2-oct-2026: $18.3688 (dolardof.com)
A10: iva | B10: IVA | C10: % | D10: 0.16 | E10: 0.16 | F10: =IF(sel_costos=1,D10,E10) -> 0.16 | G10: Tasa general. Las veladoras causan 16%.
A11: isr | B11: ISR persona moral | C11: % | D11: 0.3 | E11: 0.3 | F11: =IF(sel_costos=1,D11,E11) -> 0.3 | G11: Tasa general persona moral.
A12: ptu | B12: PTU (reparto de utilidades) | C12: % | D12: 0.1 | E12: 0.1 | F12: =IF(sel_costos=1,D12,E12) -> 0.1 | G12: Aproximación: 10% sobre utilidad acumulada positiva.
A13: fecha_inicio | B13: Primer mes del modelo | C13: fecha | D13: 46327 | E13: 46327 | F13: =IF(sel_costos=1,D13,E13) -> 46327 | G13: Noviembre 2026: piloto de Guadalupe y Navidad.
A14: semanas_mes | B14: Semanas por mes | C14: semanas | D14: 4.33 | E14: 4.33 | F14: =IF(sel_costos=1,D14,E14) -> 4.33 | G14: 52 / 12
A15: dias_habiles | B15: Días hábiles de producción al mes | C15: días | D15: 24 | E15: 24 | F15: =IF(sel_costos=1,D15,E15) -> 24 | G15: Lunes a sábado.
A16: meses_horizonte | B16: Horizonte del modelo | C16: meses | D16: 36 | E16: 36 | F16: =IF(sel_costos=1,D16,E16) -> 36 | G16: No cambiar: el modelo tiene 36 columnas mensuales.
A17: ref_refrescos | B17: Margen real de la tienda con refrescos de marca (referencia) | C17: % | D17: 0.225 | E17: 0.225 | F17: =IF(sel_costos=1,D17,E17) -> 0.225 | G17: 22–23% (eleventa.com). Sirve para mostrar que la vela le deja más a la tienda.
A18: 2. PRECIOS AL PÚBLICO (con IVA)
A19: p_sem | B19: Semanal (vaso + 7 días garantizados) | C19: $ / pza | D19: 45 | E19: 49 | F19: =IF(sel_costos=1,D19,E19) -> 49 | G19: Competencia semanal: $31.50–$34.90 (ver Competencia).
A20: p_rep | B20: Repuesto (sin vaso) | C20: $ / pza | D20: 32 | E20: 34 | F20: =IF(sel_costos=1,D20,E20) -> 34 | G20: Competencia repuesto: $15.50–$30.90.
A21: p_tem | B21: Edición de temporada (San Judas, Guadalupe, Muertos) | C21: $ / pza | D21: 59 | E21: 65 | F21: =IF(sel_costos=1,D21,E21) -> 65 | G21: Misma vela con manga premium.
A22: p_per | B22: Personalizada (foto / nombre / intención) | C22: $ / pza | D22: 89 | E22: 99 | F22: =IF(sel_costos=1,D22,E22) -> 99 | G22: Pedido por WhatsApp desde la tienda.
A23: p_corp | B23: Corporativa con logo (regalo de fin de año) | C23: $ / pza | D23: 229 | E23: 249 | F23: =IF(sel_costos=1,D23,E23) -> 249 | G23: Venta directa a empresas, sin intermediarios.
A24: p_parroquia | B24: Repuesto directo a parroquias | C24: $ / pza | D24: 40 | E24: 42 | F24: =IF(sel_costos=1,D24,E24) -> 42 | G24: Lámpara del Santísimo: arde siempre.
A25: p_rest | B25: Repuesto directo a restaurantes y hoteles | C25: $ / pza | D25: 38 | E25: 40 | F25: =IF(sel_costos=1,D25,E25) -> 40 | G25: Contrato mensual.
A26: p_premium | B26: Vela Récord premium (cera de abeja, doble pared) – precio neto recibido | C26: $ / pza | D26: 790 | E26: 850 | F26: =IF(sel_costos=1,D26,E26) -> 850 | G26: Promedio entre boutique y venta directa.
A27: p_rec_prem | B27: Recarga Vela Récord | C27: $ / pza | D27: 290 | E27: 320 | F27: =IF(sel_costos=1,D27,E27) -> 320
A28: ticket_ins | B28: Ticket promedio de insumos en línea (mechas, cera, kits) | C28: $ / pedido | D28: 289 | E28: 329 | F28: =IF(sel_costos=1,D28,E28) -> 329 | G28: Mercado Libre / Amazon / sitio propio.
A29: p_taller | B29: Taller de velas por persona | C29: $ / persona | D29: 650 | E29: 750 | F29: =IF(sel_costos=1,D29,E29) -> 750
A30: 3. MÁRGENES DEL CANAL (sobre precio al público con IVA)
A31: m_tienda | B31: Margen de la tienda / miscelánea | C31: % del precio | D31: 0.3 | E31: 0.27 | F31: =IF(sel_costos=1,D31,E31) -> 0.27 | G31: Validar con el distribuidor. Refrescos: 22–23%.
A32: m_dist | B32: Margen del distribuidor | C32: % de su venta | D32: 0.2 | E32: 0.17 | F32: =IF(sel_costos=1,D32,E32) -> 0.17 | G32: Validar con el distribuidor.
A33: org_pct | B33: Recaudación: % que se queda la parroquia o el colegio | C33: % | D33: 0.3 | E33: 0.3 | F33: =IF(sel_costos=1,D33,E33) -> 0.3 | G33: Modelo tipo 'galletas de las Girl Scouts'.
A34: 4. RENDIMIENTO DEL PRODUCTO
A35: horas_gar | B35: Horas garantizadas (7 días) | C35: horas | D35: 168 | E35: 168 | F35: =IF(sel_costos=1,D35,E35) -> 168 | G35: Promesa: 7 días o te damos otra.
A36: gph | B36: Consumo de parafina con mecha optimizada | C36: g / hora | D36: 2.6 | E36: 2.3 | F36: =IF(sel_costos=1,D36,E36) -> 2.3 | G36: VALIDAR con prueba de encendido. Mecha estándar: ~5 g/h parafina (Enrich Bodycare).
A37: residual | B37: Cera que queda sin quemar al fondo | C37: % | D37: 0.05 | E37: 0.03 | F37: =IF(sel_costos=1,D37,E37) -> 0.03 | G37: Cuello de la base metálica.
A38: 5. MATERIALES (sin IVA)
A39: paraf_usd | B39: Parafina totalmente refinada – precio internacional | C39: USD / tonelada | D39: 1461 | E39: 1461 | F39: =IF(sel_costos=1,D39,E39) -> 1461 | G39: ChemAnalyst: promedio Norteamérica Q2-2026 USD 1,461/t.
A40: factor_intern | B40: Factor de flete, importación y margen del proveedor | C40: x | D40: 1.25 | E40: 1.1 | F40: =IF(sel_costos=1,D40,E40) -> 1.1 | G40: Base: compra por costal a distribuidor. Opt: compra directa por tonelada.
A41: vaso | B41: Vaso de vidrio tipo veladora | C41: $ / pza | D41: 5.5 | E41: 4.2 | F41: =IF(sel_costos=1,D41,E41) -> 4.2 | G41: ESTIMADO: cotizar por millar con 3 vidrieras.
A42: vaso_premium | B42: Vaso premium (corporativo) | C42: $ / pza | D42: 18 | E42: 15 | F42: =IF(sel_costos=1,D42,E42) -> 15 | G42: ESTIMADO.
...

Sheet Costeo
A1: Costeo unitario por producto (escenario activo)
A2: Todo sale de Supuestos. Costos sin IVA. 'Costo en régimen' = el que aplica una vez que arranca la planta propia (si el escenario la incluye).
A4: Concepto | B4: Unidad | C4: Semanal | D4: Repuesto | E4: Temporada | F4: Personalizada | G4: Corporativa | H4: Nota
A5: Horas garantizadas | B5: horas | C5: =horas_gar -> 168 | D5: =horas_gar -> 168 | E5: =horas_gar -> 168 | F5: =horas_gar -> 168 | G5: =horas_gar -> 168
A6: Consumo de cera | B6: g / hora | C6: =gph -> 2.3 | D6: =gph -> 2.3 | E6: =gph -> 2.3 | F6: =gph -> 2.3 | G6: =gph -> 2.3
A7: Cera residual sin quemar | B7: % | C7: =residual -> 0.03 | D7: =residual -> 0.03 | E7: =residual -> 0.03 | F7: =residual -> 0.03 | G7: =residual -> 0.03
A8: Gramos de cera por pieza | B8: g | C8: =C6*C5*(1+C7) -> 397.992 | D8: =D6*D5*(1+D7) -> 397.992 | E8: =E6*E5*(1+E7) -> 397.992 | F8: =F6*F5*(1+F7) -> 397.992 | G8: =G6*G5*(1+G7) -> 397.992
A9: Precio de parafina puesta en planta | B9: $ / kg | C9: =paraf_usd*tc/1000*factor_intern -> 29.522427 | D9: =paraf_usd*tc/1000*factor_intern -> 29.522427 | E9: =paraf_usd*tc/1000*factor_intern -> 29.522427 | F9: =paraf_usd*tc/1000*factor_intern -> 29.522427 | G9: =paraf_usd*tc/1000*factor_intern -> 29.522427
A10: Cera | B10: $ | C10: =C8/1000*C9 -> 11.74969 | D10: =D8/1000*D9 -> 11.74969 | E10: =E8/1000*E9 -> 11.74969 | F10: =F8/1000*F9 -> 11.74969 | G10: =G8/1000*G9 -> 11.74969
A11: Vaso | B11: $ | C11: =vaso -> 4.2 | D11: 0 | E11: =vaso -> 4.2 | F11: =vaso -> 4.2 | G11: =vaso_premium -> 15
A12: Mecha + base metálica | B12: $ | C12: =mecha -> 0.4 | D12: =mecha -> 0.4 | E12: =mecha -> 0.4 | F12: =mecha -> 0.4 | G12: =mecha -> 0.4
A13: Etiqueta / manga estándar | B13: $ | C13: =etiqueta -> 0.75 | D13: 0 | E13: =etiqueta -> 0.75 | F13: =etiqueta -> 0.75 | G13: =etiqueta -> 0.75
A14: Extra manga premium de temporada | B14: $ | C14: 0 | D14: 0 | E14: =extra_temp -> 1.2 | F14: 0 | G14: 0
A15: Extra impresión + atención personalizada | B15: $ | C15: 0 | D15: 0 | E15: 0 | F15: =extra_impr+atencion_pers -> 5 | G15: 0
A16: Caja de regalo + logo | B16: $ | C16: 0 | D16: 0 | E16: 0 | F16: 0 | G16: =caja_regalo+logo -> 17
A17: Funda del repuesto o cartucho retornable | B17: $ | C17: =IF(sel_rep=1,0,cart_neto) -> 0 | D17: =IF(sel_rep=1,funda_rep,cart_neto) -> 0.45 | E17: =IF(sel_rep=1,0,cart_neto) -> 0 | F17: =IF(sel_rep=1,0,cart_neto) -> 0 | G17: =IF(sel_rep=1,0,cart_neto) -> 0 | H17: Supuestos D184: 1 = funda (versión 1) · 2 = cartucho retornable, en todas las piezas (ver hoja Cartucho).
A18: Caja master prorrateada | B18: $ | C18: =empaque_sem -> 0.35 | D18: =empaque_rep -> 0.22 | E18: =empaque_sem -> 0.35 | F18: =empaque_sem -> 0.35 | G18: =empaque_sem -> 0.35
A19: Flete planta → bodega del distribuidor | B19: $ | C19: =viaje/(tarimas_viaje*pzas_tarima_sem) -> 0.25 | D19: =viaje/(tarimas_viaje*pzas_tarima_rep) -> 0.11111111 | E19: =viaje/(tarimas_viaje*pzas_tarima_sem) -> 0.25 | F19: =viaje/(tarimas_viaje*pzas_tarima_sem) -> 0.25 | G19: =viaje/(tarimas_viaje*pzas_tarima_sem) -> 0.25
A20: Subtotal materiales y logística | B20: $ | C20: =SUM(C10:C19) -> 17.69969 | D20: =SUM(D10:D19) -> 12.930801 | E20: =SUM(E10:E19) -> 18.89969 | F20: =SUM(F10:F19) -> 22.69969 | G20: =SUM(G10:G19) -> 45.49969
A21: Merma | B21: $ | C21: =C20*merma -> 0.26549535 | D21: =D20*merma -> 0.19396201 | E21: =E20*merma -> 0.28349535 | F21: =F20*merma -> 0.34049535 | G21: =G20*merma -> 0.68249535
A22: MATERIALES CON MERMA | B22: $ | C22: =C20+C21 -> 17.965185 | D22: =D20+D21 -> 13.124763 | E22: =E20+E21 -> 19.183185 | F22: =F20+F21 -> 23.040185 | G22: =G20+G21 -> 46.182185
A23: Factor de transformación | B23: x | C23: 1 | D23: =factor_transf_rep -> 0.75 | E23: 1 | F23: 1 | G23: 1
A24: Transformación con maquila | B24: $ | C24: =transf_maquila*C23 -> 2.2 | D24: =transf_maquila*D23 -> 1.65 | E24: =transf_maquila*E23 -> 2.2 | F24: =transf_maquila*F23 -> 2.2 | G24: =transf_maquila*G23 -> 2.2
A25: Transformación con planta propia | B25: $ | C25: =transf_propia*C23 -> 1.239272 | D25: =transf_propia*D23 -> 0.929454 | E25: =transf_propia*E23 -> 1.239272 | F25: =transf_propia*F23 -> 1.239272 | G25: =transf_propia*G23 -> 1.239272
A26: Costo total con maquila | B26: $ | C26: =C22+C24 -> 20.165185 | D26: =D22+D24 -> 14.774763 | E26: =E22+E24 -> 21.383185 | F26: =F22+F24 -> 25.240185 | G26: =G22+G24 -> 48.382185
A27: Costo total con planta propia | B27: $ | C27: =C22+C25 -> 19.204457 | D27: =D22+D25 -> 14.054217 | E27: =E22+E25 -> 20.422457 | F27: =F22+F25 -> 24.279457 | G27: =G22+G25 -> 47.421457
A28: COSTO EN RÉGIMEN (el que usa la cascada) | B28: $ | C28: =IF(mes_planta<=meses_horizonte,C27,C26) -> 20.165185 | D28: =IF(mes_planta<=meses_horizonte,D27,D26) -> 14.774763 | E28: =IF(mes_planta<=meses_horizonte,E27,E26) -> 21.383185 | F28: =IF(mes_planta<=meses_horizonte,F27,F26) -> 25.240185 | G28: =IF(mes_planta<=meses_horizonte,G27,G26) -> 48.382185 | H28: Con planta propia si el escenario la incluye; si no, maquila.
A30: INDICADORES PARA EL CONSUMIDOR Y DE EFICIENCIA
A31: Precio al público (con IVA) | B31: $ | C31: =p_sem -> 49 | D31: =p_rep -> 34 | E31: =p_tem -> 65 | F31: =p_per -> 99 | G31: =p_corp -> 249
A32: Costo por hora de luz para el consumidor | B32: $ / hora | C32: =C31/C5 -> 0.29166667 | D32: =D31/D5 -> 0.20238095 | E32: =E31/E5 -> 0.38690476 | F32: =F31/F5 -> 0.58928571 | G32: =G31/G5 -> 1.4821429
A33: Vidrio como % del costo | B33: % | C33: =IFERROR(C11/C28,0) -> 0.20827976 | D33: =IFERROR(D11/D28,0) -> 0 | E33: =IFERROR(E11/E28,0) -> 0.19641601 | F33: =IFERROR(F11/F28,0) -> 0.16640132 | G33: =IFERROR(G11/G28,0) -> 0.31003147
A34: Cera como % del costo | B34: % | C34: =IFERROR(C10/C28,0) -> 0.58267205 | D34: =IFERROR(D10/D28,0) -> 0.79525403 | E34: =IFERROR(E10/E28,0) -> 0.54948268 | F34: =IFERROR(F10/F28,0) -> 0.4655152 | G34: =IFERROR(G10/G28,0) -> 0.24285157
A35: Kilos de cera por cada 1,000 piezas | B35: kg | C35: =C8 -> 397.992 | D35: =D8 -> 397.992 | E35: =E8 -> 397.992 | F35: =F8 -> 397.992 | G35: =G8 -> 397.992

Sheet Cartucho
A1: El cartucho retornable
A2: El repuesto es una copa de aluminio con la cera y la mecha ya puestas. Regresa vacío a la tienda, se rellena y vuelve a salir. Los datos vienen de Supuestos, sección 17.
A4: EL CICLO
A5: 1. El cliente mete el cartucho completo al vaso y lo prende. La cera arde dentro del aluminio; el vaso no se ensucia.
A6: 2. Cuando se acaba, regresa el cartucho vacío a la misma tienda y le descuentan el depósito en el siguiente.
A7: 3. La tienda junta los vacíos en una caja de 24. La ruta del distribuidor se los lleva en su visita de siempre.
A8: 4. En planta no se lava: se calienta, se saca el cabo, se pone mecha nueva y se rellena. El residuo se integra a la cera nueva.
A9: 5. Cuando un cartucho ya no sirve, el aluminio se recicla.
A11: CUÁNTO CUESTA CADA LLENADO
A12: Concepto | B12: Valor | C12: Unidad | D12: Cómo se calcula
A13: Costo de un cartucho nuevo | B13: =cart_costo -> 2.6 | C13: $ / pza | D13: Supuestos.
A14: Cartuchos que regresan | B14: =cart_retorno -> 0.8 | C14: % | D14: Supuestos. De cada 100 cartuchos vendidos, cuántos vuelven a la tienda.
A15: Vueltas máximas por cartucho | B15: =cart_vueltas -> 12 | C15: vueltas | D15: Supuestos.
A16: Llenados que da un cartucho en su vida | B16: =IF(cart_retorno>=1,cart_vueltas,(1-cart_retorno^cart_vueltas)/(1-cart_retorno)) -> 4.6564026 | C16: llenados | D16: En cada vuelta se pierde el que no regresa. Con 80% de retorno y 12 vueltas, un cartucho se llena 4.7 veces en promedio.
A17: Aluminio por llenado | B17: =B13/B16 -> 0.55837096 | C17: $ / llenado | D17: Costo del cartucho repartido entre sus llenados.
A18: Reproceso y logística inversa por llenado | B18: =cart_retorno*(cart_reproceso+cart_log_inv) -> 0.32 | C18: $ / llenado | D18: Solo aplica a los que regresan.
A19: Depósito que nadie reclama, sin IVA | B19: =(1-cart_retorno)*cart_deposito/(1+iva) -> 0.86206897 | C19: $ / llenado | D19: El cliente que no regresa el cartucho deja su depósito. Supone que ese depósito llega hasta nosotros: VALIDAR con el distribuidor.
A20: COSTO NETO DEL CARTUCHO POR LLENADO | B20: =B17+B18-B19 -> 0.016301995 | C20: $ / llenado | D20: Aluminio + reproceso − depósitos no reclamados. Es lo que entra al costeo cuando el selector está en 2.
A21: Costo sin contar los depósitos (lectura conservadora) | B21: =B17+B18 -> 0.87837096 | C21: $ / llenado | D21: Si el depósito no reclamado se queda en la tienda o en el distribuidor.
A22: Funda del repuesto (versión 1) | B22: =funda_rep -> 0.45 | C22: $ / pza | D22: Lo que hoy usa el modelo con el selector en 1.
A23: Ahorro por repuesto contra la funda | B23: =B22-B20 -> 0.43369801 | C23: $ / pza | D23: Positivo = el cartucho retornable sale más barato que la funda.
A25: QUÉ CAMBIA EN UN AÑO (año 2 del escenario activo)
A26: Concepto | B26: Valor | C26: Unidad | D26: Cómo se calcula
A27: Velas con vaso al año | B27: =Palancas!B6 -> 151805.02 | C27: pzas | D27: Cada una sale con su primer cartucho.
A28: Repuestos al año | B28: =Palancas!B7 -> 85410.036 | C28: pzas | D28: Cada uno es un llenado.
A29: Llenados al año | B29: =B27+B28 -> 237215.06 | C29: llenados
A30: Cartuchos nuevos que hay que comprar al año | B30: =B29/B16 -> 50943.847 | C30: pzas | D30: Llenados ÷ llenados por cartucho.
A31: Compra anual de cartuchos | B31: =B30*B13 -> 132454 | C31: $
A32: Reproceso y logística inversa al año | B32: =B29*B18 -> 75908.82 | C32: $
A33: Depósitos no reclamados al año, sin IVA | B33: =B29*B19 -> 204495.74 | C33: $ | D33: Ingreso que compensa los cartuchos perdidos.
A34: Costo neto anual del sistema de cartucho | B34: =B31+B32-B33 -> 3867.0787 | C34: $
A35: Costo anual de las fundas (versión 1) | B35: =B28*B22 -> 38434.516 | C35: $ | D35: Solo los repuestos llevan funda.
A36: DIFERENCIA AL AÑO: CARTUCHO RETORNABLE CONTRA FUNDA | B36: =B35-B34 -> 34567.438 | C36: $ | D36: Positivo = el cartucho deja más dinero. No incluye la merma (1.5%) ni el vidrio que se ahorra en ruta.
A38: CARTUCHOS EN CIRCULACIÓN (año 2)
A39: Concepto | B39: Valor | C39: Unidad | D39: Cómo se calcula
A40: Llenados al mes | B40: =B29/12 -> 19767.922 | C40: llenados
A41: Semanas que tarda la vuelta completa | B41: =cart_ciclo -> 4 | C41: semanas | D41: Supuestos.
A42: Cartuchos en circulación | B42: =B40*B41/semanas_mes -> 18261.36 | C42: pzas | D42: Los que hay en casas, tiendas, ruta y planta al mismo tiempo.
A43: Inversión en la flotilla de cartuchos | B43: =B42*B13 -> 47479.535 | C43: $ | D43: Se compra una vez, al arrancar. No está en la hoja Flujo.
A44: Depósitos cobrados por los cartuchos en circulación | B44: =B42*cart_deposito -> 91306.798 | C44: $ | D44: Es dinero del cliente: se le debe hasta que regrese el cartucho.
...

Sheet Cascada
A1: Cascada de precios: quién gana qué en cada pieza (escenario activo)
A2: Márgenes de tienda y distribuidor calculados sobre precio con IVA, como se negocia en la calle. Nuestro ingreso es sin IVA.
A4: Concepto | B4: Semanal | C4: Repuesto | D4: Temporada | E4: Personalizada | F4: Nota
A5: Precio al público (con IVA) | B5: =p_sem -> 49 | C5: =p_rep -> 34 | D5: =p_tem -> 65 | E5: =p_per -> 99
A6: Precio al público sin IVA | B6: =B5/(1+iva) -> 42.241379 | C6: =C5/(1+iva) -> 29.310345 | D6: =D5/(1+iva) -> 56.034483 | E6: =E5/(1+iva) -> 85.344828
A7: IVA total en el precio al público | B7: =B5-B6 -> 6.7586207 | C7: =C5-C6 -> 4.6896552 | D7: =D5-D6 -> 8.9655172 | E7: =E5-E6 -> 13.655172
A8: La tienda compra a (con IVA) | B8: =B5*(1-m_tienda) -> 35.77 | C8: =C5*(1-m_tienda) -> 24.82 | D8: =D5*(1-m_tienda) -> 47.45 | E8: =E5*(1-m_tienda) -> 72.27
A9: LA TIENDA GANA por pieza | B9: =B5-B8 -> 13.23 | C9: =C5-C8 -> 9.18 | D9: =D5-D8 -> 17.55 | E9: =E5-E8 -> 26.73
A10: El distribuidor compra a (con IVA) | B10: =B8*(1-m_dist) -> 29.6891 | C10: =C8*(1-m_dist) -> 20.6006 | D10: =D8*(1-m_dist) -> 39.3835 | E10: =E8*(1-m_dist) -> 59.9841
A11: EL DISTRIBUIDOR GANA por pieza | B11: =B8-B10 -> 6.0809 | C11: =C8-C10 -> 4.2194 | D11: =D8-D10 -> 8.0665 | E11: =E8-E10 -> 12.2859
A12: Nuestro precio neto (sin IVA) | B12: =B10/(1+iva) -> 25.594052 | C12: =C10/(1+iva) -> 17.759138 | D12: =D10/(1+iva) -> 33.951293 | E12: =E10/(1+iva) -> 51.710431
A13: Nuestro costo en régimen | B13: =Costeo!C28 -> 20.165185 | C13: =Costeo!D28 -> 14.774763 | D13: =Costeo!E28 -> 21.383185 | E13: =Costeo!F28 -> 25.240185
A14: NOSOTROS GANAMOS por pieza (utilidad bruta) | B14: =B12-B13 -> 5.4288666 | C14: =C12-C13 -> 2.984375 | D14: =D12-D13 -> 12.568108 | E14: =E12-E13 -> 26.470246
A15: Nuestro margen bruto | B15: =IFERROR(B14/B12,0) -> 0.21211439 | C15: =IFERROR(C14/C12,0) -> 0.16804729 | D15: =IFERROR(D14/D12,0) -> 0.37018054 | E15: =IFERROR(E14/E12,0) -> 0.51189374
A17: ¿A DÓNDE SE VA CADA PESO QUE PAGA EL CLIENTE?
A18: Tienda | B18: =B9/B5 -> 0.27 | C18: =C9/C5 -> 0.27 | D18: =D9/D5 -> 0.27 | E18: =E9/E5 -> 0.27
A19: Distribuidor | B19: =B11/B5 -> 0.1241 | C19: =C11/C5 -> 0.1241 | D19: =D11/D5 -> 0.1241 | E19: =E11/E5 -> 0.1241
A20: IVA de nuestra factura (SAT) | B20: =(B10-B12)/B5 -> 0.083572414 | C20: =(C10-C12)/C5 -> 0.083572414 | D20: =(D10-D12)/D5 -> 0.083572414 | E20: =(E10-E12)/E5 -> 0.083572414
A21: Costo de producir | B21: =B13/B5 -> 0.41153439 | C21: =C13/C5 -> 0.43455185 | D21: =D13/D5 -> 0.32897208 | E21: =E13/E5 -> 0.25495136
A22: Nuestra utilidad | B22: =B14/B5 -> 0.1107932 | C22: =C14/C5 -> 0.087775736 | D22: =D14/D5 -> 0.19335551 | E22: =E14/E5 -> 0.26737622
A23: Total (control = 100%) | B23: =SUM(B18:B22) -> 1 | C23: =SUM(C18:C22) -> 1 | D23: =SUM(D18:D22) -> 1 | E23: =SUM(E18:E22) -> 1
A25: PROMEDIOS PONDERADOS POR LA MEZCLA (por pieza vendida al distribuidor)
A26: Mezcla temporada normal | B26: =mix_sem -> 0.35 | C26: =mix_rep -> 0.4 | D26: =mix_tem -> 0.18 | E26: =mix_per -> 0.07
A27: Mezcla temporada alta | B27: =mix_alta_sem -> 0.3 | C27: =mix_alta_rep -> 0.3 | D27: =mix_alta_tem -> 0.32 | E27: =mix_alta_per -> 0.08
A28: Nuestra utilidad ponderada por pieza (normal) | B28: =SUMPRODUCT($B$26:$E$26,$B$14:$E$14) -> 7.20903
A29: Nuestra utilidad ponderada por pieza (temporada alta) | B29: =SUMPRODUCT($B$27:$E$27,$B$14:$E$14) -> 8.6633867
A30: Precio al público ponderado (normal) | B30: =SUMPRODUCT($B$26:$E$26,$B$5:$E$5) -> 49.38
A31: La tienda gana ponderado por pieza (normal) | B31: =SUMPRODUCT($B$26:$E$26,$B$9:$E$9) -> 13.3326
A32: El distribuidor gana ponderado por pieza (normal) | B32: =SUMPRODUCT($B$26:$E$26,$B$11:$E$11) -> 6.128058
A33: Nuestro ingreso neto ponderado por pieza (normal) | B33: =SUMPRODUCT($B$26:$E$26,$B$12:$E$12) -> 25.792536
A34: Nuestro costo ponderado por pieza (normal) | B34: =SUMPRODUCT($B$26:$E$26,$B$13:$E$13) -> 18.583506
A36: CANALES DIRECTOS: ECONOMÍA POR UNIDAD
A37: Canal | B37: Precio con IVA | C37: Neto sin IVA | D37: Costo | E37: Utilidad por unidad | F37: Margen | G37: Unidad
A38: Parroquias (repuesto directo) | B38: =p_parroquia -> 42 | C38: =B38/(1+iva) -> 36.206897 | D38: =cost_rep -> 14.774763 | E38: =C38-D38 -> 21.432134 | F38: =IFERROR(E38/C38,0) -> 0.59193512 | G38: pieza
A39: Restaurantes y hoteles (repuesto directo) | B39: =p_rest -> 40 | C39: =B39/(1+iva) -> 34.482759 | D39: =cost_rep -> 14.774763 | E39: =C39-D39 -> 19.707996 | F39: =IFERROR(E39/C39,0) -> 0.57153188 | G39: pieza
A40: Recaudación con colegios y parroquias (semanal) | B40: =p_sem -> 49 | C40: =B40*(1-org_pct)/(1+iva) -> 29.568966 | D40: =cost_sem -> 20.165185 | E40: =C40-D40 -> 9.4037804 | F40: =IFERROR(E40/C40,0) -> 0.31802873 | G40: pieza
A41: Regalo corporativo con logo | B41: =p_corp -> 249 | C41: =B41/(1+iva) -> 214.65517 | D41: =cost_corp -> 48.382185 | E41: =C41-D41 -> 166.27299 | F41: =IFERROR(E41/C41,0) -> 0.77460508 | G41: pieza
A42: Vela Récord premium | B42: =p_premium -> 850 | C42: =B42/(1+iva) -> 732.75862 | D42: =costo_prem -> 320 | E42: =C42-D42 -> 412.75862 | F42: =IFERROR(E42/C42,0) -> 0.56329412 | G42: pieza
A43: Recarga Vela Récord | B43: =p_rec_prem -> 320 | C43: =B43/(1+iva) -> 275.86207 | D43: =costo_rec_prem -> 120 | E43: =C43-D43 -> 155.86207 | F43: =IFERROR(E43/C43,0) -> 0.565 | G43: pieza
A44: Insumos en línea (después de comisión, envío y publicidad) | B44: =ticket_ins -> 329 | C44: =B44/(1+iva) -> 283.62069 | D44: =C44*(costo_ins_pct+comision_mp+publicidad_ins)+envio_ins -> 235.31897 | E44: =C44-D44 -> 48.301724 | F44: =IFERROR(E44/C44,0) -> 0.17030395 | G44: pedido
...

Sheet Volumen
A1: Volumen mensual (36 meses, escenario activo)
A2: Piezas facturadas al distribuidor = venta a consumidor (sell-through) + carga inicial de cada tienda nueva.
A3: Mes # | C3: 1 | D3: 2 | E3: 3 | F3: 4 | G3: 5 | H3: 6 | I3: 7 | J3: 8 | K3: 9 | L3: 10 | M3: 11 | N3: 12 | O3: 13 | P3: 14 | Q3: 15 | R3: 16 | S3: 17 | T3: 18 | U3: 19 | V3: 20 | W3: 21 | X3: 22 | Y3: 23 | Z3: 24 | AA3: 25 | AB3: 26 | AC3: 27 | AD3: 28 | AE3: 29 | AF3: 30 | AG3: 31 | AH3: 32 | AI3: 33 | AJ3: 34 | AK3: 35 | AL3: 36
A4: Fecha | C4: =fecha_inicio -> 46327 | D4: =DATE(YEAR(C4),MONTH(C4)+1,1) -> 46357 | E4: =DATE(YEAR(D4),MONTH(D4)+1,1) -> 46388 | F4: =DATE(YEAR(E4),MONTH(E4)+1,1) -> 46419 | G4: =DATE(YEAR(F4),MONTH(F4)+1,1) -> 46447 | H4: =DATE(YEAR(G4),MONTH(G4)+1,1) -> 46478 | I4: =DATE(YEAR(H4),MONTH(H4)+1,1) -> 46508 | J4: =DATE(YEAR(I4),MONTH(I4)+1,1) -> 46539 | K4: =DATE(YEAR(J4),MONTH(J4)+1,1) -> 46569 | ... AL4: =DATE(YEAR(AK4),MONTH(AK4)+1,1) -> 47392
A5: Mes calendario | C5: =MONTH(C4) -> 11 | D5: =MONTH(D4) -> 12 | E5: =MONTH(E4) -> 1 | F5: =MONTH(F4) -> 2 | G5: =MONTH(G4) -> 3 | H5: =MONTH(H4) -> 4 | I5: =MONTH(I4) -> 5 | J5: =MONTH(J4) -> 6 | ... AL5: =MONTH(AL4) -> 10
A6: Año del modelo | C6: =ROUNDUP(C3/12,0) -> 1 | D6: =ROUNDUP(D3/12,0) -> 1 | E6: =ROUNDUP(E3/12,0) -> 1 | F6: =ROUNDUP(F3/12,0) -> 1 | G6: =ROUNDUP(G3/12,0) -> 1 | H6: =ROUNDUP(H3/12,0) -> 1 | I6: =ROUNDUP(I3/12,0) -> 1 | J6: =ROUNDUP(J3/12,0) -> 1 | ... AL6: =ROUNDUP(AL3/12,0) -> 3
A7: Índice estacional | B7: x | C7: =INDEX(est_idx,C5)/AVERAGE(est_idx) -> 1.78125 | D7: =INDEX(est_idx,D5)/AVERAGE(est_idx) -> 1.40625 | E7: =INDEX(est_idx,E5)/AVERAGE(est_idx) -> 0.75 | F7: =INDEX(est_idx,F5)/AVERAGE(est_idx) -> 0.796875 | G7: =INDEX(est_idx,G5)/AVERAGE(est_idx) -> 0.890625 | H7: =INDEX(est_idx,H5)/AVERAGE(est_idx) -> 0.9375 | I7: =INDEX(est_idx,I5)/AVERAGE(est_idx) -> 0.890625 | J7: =INDEX(est_idx,J5)/AVERAGE(est_idx) -> 0.75 | ... AL7: =INDEX(est_idx,AL5)/AVERAGE(est_idx) -> 1.5
A8: Temporada alta | B8: 1/0 | C8: =INDEX(est_flag,C5) -> 1 | D8: =INDEX(est_flag,D5) -> 1 | E8: =INDEX(est_flag,E5) -> 0 | F8: =INDEX(est_flag,F5) -> 0 | G8: =INDEX(est_flag,G5) -> 0 | H8: =INDEX(est_flag,H5) -> 0 | I8: =INDEX(est_flag,I5) -> 0 | J8: =INDEX(est_flag,J5) -> 0 | ... AL8: =INDEX(est_flag,AL5) -> 1
A10: CANAL DISTRIBUIDOR
A11: Tiendas activas | B11: tiendas | C11: =ROUND(MIN(tiendas_universo,IF(C$3<=meses_piloto,tiendas_piloto,tiendas_piloto+(tiendas_meta-tiendas_piloto)*MIN(1,(C$3-meses_piloto)/meses_rampa))),0) -> 50 | D11: =ROUND(MIN(tiendas_universo,IF(D$3<=meses_piloto,tiendas_piloto,tiendas_piloto+(tiendas_meta-tiendas_piloto)*MIN(1,(D$3-meses_piloto)/meses_rampa))),0) -> 50 | E11: =ROUND(MIN(tiendas_universo,IF(E$3<=meses_piloto,tiendas_piloto,tiendas_piloto+(tiendas_meta-tiendas_piloto)*MIN(1,(E$3-meses_piloto)/meses_rampa))),0) -> 125 | F11: =ROUND(MIN(tiendas_universo,IF(F$3<=meses_piloto,tiendas_piloto,tiendas_piloto+(tiendas_meta-tiendas_piloto)*MIN(1,(F$3-meses_piloto)/meses_rampa))),0) -> 200 | G11: =ROUND(MIN(tiendas_universo,IF(G$3<=meses_piloto,tiendas_piloto,tiendas_piloto+(tiendas_meta-tiendas_piloto)*MIN(1,(G$3-meses_piloto)/meses_rampa))),0) -> 275 | H11: =ROUND(MIN(tiendas_universo,IF(H$3<=meses_piloto,tiendas_piloto,tiendas_piloto+(tiendas_meta-tiendas_piloto)*MIN(1,(H$3-meses_piloto)/meses_rampa))),0) -> 350 | I11: =ROUND(MIN(tiendas_universo,IF(I$3<=meses_piloto,tiendas_piloto,tiendas_piloto+(tiendas_meta-tiendas_piloto)*MIN(1,(I$3-meses_piloto)/meses_rampa))),0) -> 425 | J11: =ROUND(MIN(tiendas_universo,IF(J$3<=meses_piloto,tiendas_piloto,tiendas_piloto+(tiendas_meta-tiendas_piloto)*MIN(1,(J$3-meses_piloto)/meses_rampa))),0) -> 500 | ... AL11: =ROUND(MIN(tiendas_universo,IF(AL$3<=meses_piloto,tiendas_piloto,tiendas_piloto+(tiendas_meta-tiendas_piloto)*MIN(1,(AL$3-meses_piloto)/meses_rampa))),0) -> 500
A12: Tiendas nuevas en el mes | B12: tiendas | C12: =C11 -> 50 | D12: =MAX(0,D11-C11) -> 0 | E12: =MAX(0,E11-D11) -> 75 | F12: =MAX(0,F11-E11) -> 75 | G12: =MAX(0,G11-F11) -> 75 | H12: =MAX(0,H11-G11) -> 75 | I12: =MAX(0,I11-H11) -> 75 | J12: =MAX(0,J11-I11) -> 75 | K12: =MAX(0,K11-J11) -> 0 | ... AL12: =MAX(0,AL11-AK11) -> 0
A13: Piezas por tienda por semana | B13: pzas | C13: =uds_sem*(1+crec_anual)^(C$6-1) -> 8 | D13: =uds_sem*(1+crec_anual)^(D$6-1) -> 8 | E13: =uds_sem*(1+crec_anual)^(E$6-1) -> 8 | F13: =uds_sem*(1+crec_anual)^(F$6-1) -> 8 | G13: =uds_sem*(1+crec_anual)^(G$6-1) -> 8 | H13: =uds_sem*(1+crec_anual)^(H$6-1) -> 8 | I13: =uds_sem*(1+crec_anual)^(I$6-1) -> 8 | J13: =uds_sem*(1+crec_anual)^(J$6-1) -> 8 | ... AL13: =uds_sem*(1+crec_anual)^(AL$6-1) -> 9.68
A14: Venta al consumidor (sell-through) | B14: pzas | C14: =C11*C13*semanas_mes*C$7 -> 3085.125 | D14: =D11*D13*semanas_mes*D$7 -> 2435.625 | E14: =E11*E13*semanas_mes*E$7 -> 3247.5 | F14: =F11*F13*semanas_mes*F$7 -> 5520.75 | G14: =G11*G13*semanas_mes*G$7 -> 8484.0938 | H14: =H11*H13*semanas_mes*H$7 -> 11366.25 | I14: =I11*I13*semanas_mes*I$7 -> 13111.781 | J14: =J11*J13*semanas_mes*J$7 -> 12990 | ... AL14: =AL11*AL13*semanas_mes*AL$7 -> 31435.8
A15: Carga inicial de tiendas nuevas | B15: pzas | C15: =C12*carga_inicial -> 1200 | D15: =D12*carga_inicial -> 0 | E15: =E12*carga_inicial -> 1800 | F15: =F12*carga_inicial -> 1800 | G15: =G12*carga_inicial -> 1800 | H15: =H12*carga_inicial -> 1800 | I15: =I12*carga_inicial -> 1800 | J15: =J12*carga_inicial -> 1800 | ... AL15: =AL12*carga_inicial -> 0
A16: PIEZAS FACTURADAS AL DISTRIBUIDOR | B16: pzas | C16: =C14+C15 -> 4285.125 | D16: =D14+D15 -> 2435.625 | E16: =E14+E15 -> 5047.5 | F16: =F14+F15 -> 7320.75 | G16: =G14+G15 -> 10284.094 | H16: =H14+H15 -> 13166.25 | I16: =I14+I15 -> 14911.781 | J16: =J14+J15 -> 14790 | ... AL16: =AL14+AL15 -> 31435.8
A17: Mezcla Semanal | B17: % | C17: =IF(C$8=1,mix_alta_sem,mix_sem) -> 0.3 | D17: =IF(D$8=1,mix_alta_sem,mix_sem) -> 0.3 | E17: =IF(E$8=1,mix_alta_sem,mix_sem) -> 0.35 | F17: =IF(F$8=1,mix_alta_sem,mix_sem) -> 0.35 | G17: =IF(G$8=1,mix_alta_sem,mix_sem) -> 0.35 | H17: =IF(H$8=1,mix_alta_sem,mix_sem) -> 0.35 | I17: =IF(I$8=1,mix_alta_sem,mix_sem) -> 0.35 | J17: =IF(J$8=1,mix_alta_sem,mix_sem) -> 0.35 | ... AL17: =IF(AL$8=1,mix_alta_sem,mix_sem) -> 0.3
A18: Mezcla Repuesto | B18: % | C18: =IF(C$8=1,mix_alta_rep,mix_rep) -> 0.3 | D18: =IF(D$8=1,mix_alta_rep,mix_rep) -> 0.3 | E18: =IF(E$8=1,mix_alta_rep,mix_rep) -> 0.4 | F18: =IF(F$8=1,mix_alta_rep,mix_rep) -> 0.4 | G18: =IF(G$8=1,mix_alta_rep,mix_rep) -> 0.4 | H18: =IF(H$8=1,mix_alta_rep,mix_rep) -> 0.4 | I18: =IF(I$8=1,mix_alta_rep,mix_rep) -> 0.4 | J18: =IF(J$8=1,mix_alta_rep,mix_rep) -> 0.4 | ... AL18: =IF(AL$8=1,mix_alta_rep,mix_rep) -> 0.3
A19: Mezcla Temporada | B19: % | C19: =IF(C$8=1,mix_alta_tem,mix_tem) -> 0.32 | D19: =IF(D$8=1,mix_alta_tem,mix_tem) -> 0.32 | E19: =IF(E$8=1,mix_alta_tem,mix_tem) -> 0.18 | F19: =IF(F$8=1,mix_alta_tem,mix_tem) -> 0.18 | G19: =IF(G$8=1,mix_alta_tem,mix_tem) -> 0.18 | H19: =IF(H$8=1,mix_alta_tem,mix_tem) -> 0.18 | I19: =IF(I$8=1,mix_alta_tem,mix_tem) -> 0.18 | J19: =IF(J$8=1,mix_alta_tem,mix_tem) -> 0.18 | ... AL19: =IF(AL$8=1,mix_alta_tem,mix_tem) -> 0.32
A20: Mezcla Personalizada | B20: % | C20: =IF(C$8=1,mix_alta_per,mix_per) -> 0.08 | D20: =IF(D$8=1,mix_alta_per,mix_per) -> 0.08 | E20: =IF(E$8=1,mix_alta_per,mix_per) -> 0.07 | F20: =IF(F$8=1,mix_alta_per,mix_per) -> 0.07 | G20: =IF(G$8=1,mix_alta_per,mix_per) -> 0.07 | H20: =IF(H$8=1,mix_alta_per,mix_per) -> 0.07 | I20: =IF(I$8=1,mix_alta_per,mix_per) -> 0.07 | J20: =IF(J$8=1,mix_alta_per,mix_per) -> 0.07 | ... AL20: =IF(AL$8=1,mix_alta_per,mix_per) -> 0.08
A21: Piezas Semanal | B21: pzas | C21: =C16*C17 -> 1285.5375 | D21: =D16*D17 -> 730.6875 | E21: =E16*E17 -> 1766.625 | F21: =F16*F17 -> 2562.2625 | G21: =G16*G17 -> 3599.4328 | H21: =H16*H17 -> 4608.1875 | I21: =I16*I17 -> 5219.1234 | J21: =J16*J17 -> 5176.5 | ... AL21: =AL16*AL17 -> 9430.74
A22: Piezas Repuesto | B22: pzas | C22: =C16*C18 -> 1285.5375 | D22: =D16*D18 -> 730.6875 | E22: =E16*E18 -> 2019 | F22: =F16*F18 -> 2928.3 | G22: =G16*G18 -> 4113.6375 | H22: =H16*H18 -> 5266.5 | I22: =I16*I18 -> 5964.7125 | J22: =J16*J18 -> 5916 | ... AL22: =AL16*AL18 -> 9430.74
A23: Piezas Temporada | B23: pzas | C23: =C16*C19 -> 1371.24 | D23: =D16*D19 -> 779.4 | E23: =E16*E19 -> 908.55 | F23: =F16*F19 -> 1317.735 | G23: =G16*G19 -> 1851.1369 | H23: =H16*H19 -> 2369.925 | I23: =I16*I19 -> 2684.1206 | J23: =J16*J19 -> 2662.2 | ... AL23: =AL16*AL19 -> 10059.456
A24: Piezas Personalizada | B24: pzas | C24: =C16*C20 -> 342.81 | D24: =D16*D20 -> 194.85 | E24: =E16*E20 -> 353.325 | F24: =F16*F20 -> 512.4525 | G24: =G16*G20 -> 719.88656 | H24: =H16*H20 -> 921.6375 | I24: =I16*I20 -> 1043.8247 | J24: =J16*J20 -> 1035.3 | ... AL24: =AL16*AL20 -> 2514.864
A25: Devoluciones por venta garantizada | B25: pzas | C25: =C15*pct_devol -> 48 | D25: =D15*pct_devol -> 0 | E25: =E15*pct_devol -> 72 | F25: =F15*pct_devol -> 72 | G25: =G15*pct_devol -> 72 | H25: =H15*pct_devol -> 72 | I25: =I15*pct_devol -> 72 | J25: =J15*pct_devol -> 72 | ... AL25: =AL15*pct_devol -> 0
A27: CANALES DIRECTOS
A28: Parroquias activas | B28: parroquias | C28: =IF(C$3<inicio_parr,0,MIN(1,(C$3-inicio_parr+1)/rampa_parr))*parroquias_total*adop_parr -> 0 | D28: =IF(D$3<inicio_parr,0,MIN(1,(D$3-inicio_parr+1)/rampa_parr))*parroquias_total*adop_parr -> 2.125 | E28: =IF(E$3<inicio_parr,0,MIN(1,(E$3-inicio_parr+1)/rampa_parr))*parroquias_total*adop_parr -> 4.25 | F28: =IF(F$3<inicio_parr,0,MIN(1,(F$3-inicio_parr+1)/rampa_parr))*parroquias_total*adop_parr -> 6.375 | G28: =IF(G$3<inicio_parr,0,MIN(1,(G$3-inicio_parr+1)/rampa_parr))*parroquias_total*adop_parr -> 8.5 | H28: =IF(H$3<inicio_parr,0,MIN(1,(H$3-inicio_parr+1)/rampa_parr))*parroquias_total*adop_parr -> 10.625 | I28: =IF(I$3<inicio_parr,0,MIN(1,(I$3-inicio_parr+1)/rampa_parr))*parroquias_total*adop_parr -> 12.75 | J28: =IF(J$3<inicio_parr,0,MIN(1,(J$3-inicio_parr+1)/rampa_parr))*parroquias_total*adop_parr -> 12.75 | ... AL28: =IF(AL$3<inicio_parr,0,MIN(1,(AL$3-inicio_parr+1)/rampa_parr))*parroquias_total*adop_parr -> 12.75
A29: Repuestos a parroquias | B29: pzas | C29: =C28*rep_sem_parr*semanas_mes -> 0 | D29: =D28*rep_sem_parr*semanas_mes -> 9.20125 | E29: =E28*rep_sem_parr*semanas_mes -> 18.4025 | F29: =F28*rep_sem_parr*semanas_mes -> 27.60375 | G29: =G28*rep_sem_parr*semanas_mes -> 36.805 | H29: =H28*rep_sem_parr*semanas_mes -> 46.00625 | I29: =I28*rep_sem_parr*semanas_mes -> 55.2075 | J29: =J28*rep_sem_parr*semanas_mes -> 55.2075 | ... AL29: =AL28*rep_sem_parr*semanas_mes -> 55.2075
A30: Restaurantes y hoteles activos | B30: clientes | C30: =IF(C$3<inicio_rest,0,MIN(1,(C$3-inicio_rest+1)/rampa_rest))*rest_meta -> 0 | D30: =IF(D$3<inicio_rest,0,MIN(1,(D$3-inicio_rest+1)/rampa_rest))*rest_meta -> 0 | E30: =IF(E$3<inicio_rest,0,MIN(1,(E$3-inicio_rest+1)/rampa_rest))*rest_meta -> 2.2222222 | F30: =IF(F$3<inicio_rest,0,MIN(1,(F$3-inicio_rest+1)/rampa_rest))*rest_meta -> 4.4444444 | G30: =IF(G$3<inicio_rest,0,MIN(1,(G$3-inicio_rest+1)/rampa_rest))*rest_meta -> 6.6666667 | H30: =IF(H$3<inicio_rest,0,MIN(1,(H$3-inicio_rest+1)/rampa_rest))*rest_meta -> 8.8888889 | I30: =IF(I$3<inicio_rest,0,MIN(1,(I$3-inicio_rest+1)/rampa_rest))*rest_meta -> 11.111111 | J30: =IF(J$3<inicio_rest,0,MIN(1,(J$3-inicio_rest+1)/rampa_rest))*rest_meta -> 13.333333 | ... AL30: =IF(AL$3<inicio_rest,0,MIN(1,(AL$3-inicio_rest+1)/rampa_rest))*rest_meta -> 20
A31: Repuestos a restaurantes y hoteles | B31: pzas | C31: =C30*mesas_rest*horas_noche*noches_mes/horas_gar -> 0 | D31: =D30*mesas_rest*horas_noche*noches_mes/horas_gar -> 0 | E31: =E30*mesas_rest*horas_noche*noches_mes/horas_gar -> 20.634921 | F31: =F30*mesas_rest*horas_noche*noches_mes/horas_gar -> 41.269841 | G31: =G30*mesas_rest*horas_noche*noches_mes/horas_gar -> 61.904762 | H31: =H30*mesas_rest*horas_noche*noches_mes/horas_gar -> 82.539683 | I31: =I30*mesas_rest*horas_noche*noches_mes/horas_gar -> 103.1746 | J31: =J30*mesas_rest*horas_noche*noches_mes/horas_gar -> 123.80952 | ... AL31: =AL30*mesas_rest*horas_noche*noches_mes/horas_gar -> 185.71429
A32: Campañas de recaudación | B32: campañas | C32: =IF(C$3<inicio_recaud,0,IF(C$8=1,campanas_alta,campanas_normal)) -> 0 | D32: =IF(D$3<inicio_recaud,0,IF(D$8=1,campanas_alta,campanas_normal)) -> 4 | E32: =IF(E$3<inicio_recaud,0,IF(E$8=1,campanas_alta,campanas_normal)) -> 2 | F32: =IF(F$3<inicio_recaud,0,IF(F$8=1,campanas_alta,campanas_normal)) -> 2 | G32: =IF(G$3<inicio_recaud,0,IF(G$8=1,campanas_alta,campanas_normal)) -> 2 | H32: =IF(H$3<inicio_recaud,0,IF(H$8=1,campanas_alta,campanas_normal)) -> 2 | I32: =IF(I$3<inicio_recaud,0,IF(I$8=1,campanas_alta,campanas_normal)) -> 2 | J32: =IF(J$3<inicio_recaud,0,IF(J$8=1,campanas_alta,campanas_normal)) -> 2 | ... AL32: =IF(AL$3<inicio_recaud,0,IF(AL$8=1,campanas_alta,campanas_normal)) -> 4
A33: Piezas de recaudación | B33: pzas | C33: =C32*pzas_campana -> 0 | D33: =D32*pzas_campana -> 600 | E33: =E32*pzas_campana -> 300 | F33: =F32*pzas_campana -> 300 | G33: =G32*pzas_campana -> 300 | H33: =H32*pzas_campana -> 300 | I33: =I32*pzas_campana -> 300 | J33: =J32*pzas_campana -> 300 | ... AL33: =AL32*pzas_campana -> 600
A34: Pedidos corporativos (noviembre y diciembre) | B34: pedidos | C34: =IF(OR(C$5=11,C$5=12),pedidos_corp,0) -> 5 | D34: =IF(OR(D$5=11,D$5=12),pedidos_corp,0) -> 5 | E34: =IF(OR(E$5=11,E$5=12),pedidos_corp,0) -> 0 | F34: =IF(OR(F$5=11,F$5=12),pedidos_corp,0) -> 0 | G34: =IF(OR(G$5=11,G$5=12),pedidos_corp,0) -> 0 | H34: =IF(OR(H$5=11,H$5=12),pedidos_corp,0) -> 0 | I34: =IF(OR(I$5=11,I$5=12),pedidos_corp,0) -> 0 | J34: =IF(OR(J$5=11,J$5=12),pedidos_corp,0) -> 0 | ... AL34: =IF(OR(AL$5=11,AL$5=12),pedidos_corp,0) -> 0
A35: Piezas corporativas | B35: pzas | C35: =C34*pzas_pedido_corp -> 600 | D35: =D34*pzas_pedido_corp -> 600 | E35: =E34*pzas_pedido_corp -> 0 | F35: =F34*pzas_pedido_corp -> 0 | G35: =G34*pzas_pedido_corp -> 0 | H35: =H34*pzas_pedido_corp -> 0 | I35: =I34*pzas_pedido_corp -> 0 | J35: =J34*pzas_pedido_corp -> 0 | ... AL35: =AL34*pzas_pedido_corp -> 0
A36: Velas Récord premium | B36: pzas | C36: =IF(C$3<inicio_prem,0,unid_prem*C$7) -> 0 | D36: =IF(D$3<inicio_prem,0,unid_prem*D$7) -> 0 | E36: =IF(E$3<inicio_prem,0,unid_prem*E$7) -> 0 | F36: =IF(F$3<inicio_prem,0,unid_prem*F$7) -> 31.875 | G36: =IF(G$3<inicio_prem,0,unid_prem*G$7) -> 35.625 | H36: =IF(H$3<inicio_prem,0,unid_prem*H$7) -> 37.5 | I36: =IF(I$3<inicio_prem,0,unid_prem*I$7) -> 35.625 | J36: =IF(J$3<inicio_prem,0,unid_prem*J$7) -> 30 | ... AL36: =IF(AL$3<inicio_prem,0,unid_prem*AL$7) -> 60
A37: Recargas Vela Récord | B37: pzas | C37: =IF(C$3<inicio_prem+2,0,unid_rec_prem) -> 0 | D37: =IF(D$3<inicio_prem+2,0,unid_rec_prem) -> 0 | E37: =IF(E$3<inicio_prem+2,0,unid_rec_prem) -> 0 | F37: =IF(F$3<inicio_prem+2,0,unid_rec_prem) -> 0 | G37: =IF(G$3<inicio_prem+2,0,unid_rec_prem) -> 0 | H37: =IF(H$3<inicio_prem+2,0,unid_rec_prem) -> 25 | I37: =IF(I$3<inicio_prem+2,0,unid_rec_prem) -> 25 | J37: =IF(J$3<inicio_prem+2,0,unid_rec_prem) -> 25 | ... AL37: =IF(AL$3<inicio_prem+2,0,unid_rec_prem) -> 25
A38: Pedidos de insumos en línea | B38: pedidos | C38: =IF(C$3<inicio_ins,0,MIN(1,(C$3-inicio_ins+1)/rampa_ins))*pedidos_ins_meta -> 0 | D38: =IF(D$3<inicio_ins,0,MIN(1,(D$3-inicio_ins+1)/rampa_ins))*pedidos_ins_meta -> 31.25 | E38: =IF(E$3<inicio_ins,0,MIN(1,(E$3-inicio_ins+1)/rampa_ins))*pedidos_ins_meta -> 62.5 | F38: =IF(F$3<inicio_ins,0,MIN(1,(F$3-inicio_ins+1)/rampa_ins))*pedidos_ins_meta -> 93.75 | G38: =IF(G$3<inicio_ins,0,MIN(1,(G$3-inicio_ins+1)/rampa_ins))*pedidos_ins_meta -> 125 | H38: =IF(H$3<inicio_ins,0,MIN(1,(H$3-inicio_ins+1)/rampa_ins))*pedidos_ins_meta -> 156.25 | I38: =IF(I$3<inicio_ins,0,MIN(1,(I$3-inicio_ins+1)/rampa_ins))*pedidos_ins_meta -> 187.5 | J38: =IF(J$3<inicio_ins,0,MIN(1,(J$3-inicio_ins+1)/rampa_ins))*pedidos_ins_meta -> 218.75 | ... AL38: =IF(AL$3<inicio_ins,0,MIN(1,(AL$3-inicio_ins+1)/rampa_ins))*pedidos_ins_meta -> 250
A39: Talleres | B39: talleres | C39: =IF(C$3<inicio_taller,0,talleres_mes) -> 0 | D39: =IF(D$3<inicio_taller,0,talleres_mes) -> 4 | E39: =IF(E$3<inicio_taller,0,talleres_mes) -> 4 | F39: =IF(F$3<inicio_taller,0,talleres_mes) -> 4 | G39: =IF(G$3<inicio_taller,0,talleres_mes) -> 4 | H39: =IF(H$3<inicio_taller,0,talleres_mes) -> 4 | I39: =IF(I$3<inicio_taller,0,talleres_mes) -> 4 | J39: =IF(J$3<inicio_taller,0,talleres_mes) -> 4 | ... AL39: =IF(AL$3<inicio_taller,0,talleres_mes) -> 4
A40: Asistentes a talleres | B40: personas | C40: =C39*asist_taller -> 0 | D40: =D39*asist_taller -> 48 | E40: =E39*asist_taller -> 48 | F40: =F39*asist_taller -> 48 | G40: =G39*asist_taller -> 48 | H40: =H39*asist_taller -> 48 | I40: =I39*asist_taller -> 48 | J40: =J39*asist_taller -> 48 | ... AL40: =AL39*asist_taller -> 48
A42: TOTALES DE PRODUCCIÓN
A43: VELAS A PRODUCIR (parafina, todos los canales) | B43: pzas | C43: =SUM(C21:C24)+C29+C31+C33+C35 -> 4885.125 | D43: =SUM(D21:D24)+D29+D31+D33+D35 -> 3644.8263 | E43: =SUM(E21:E24)+E29+E31+E33+E35 -> 5386.5374 | F43: =SUM(F21:F24)+F29+F31+F33+F35 -> 7689.6236 | G43: =SUM(G21:G24)+G29+G31+G33+G35 -> 10682.804 | H43: =SUM(H21:H24)+H29+H31+H33+H35 -> 13594.796 | I43: =SUM(I21:I24)+I29+I31+I33+I35 -> 15370.163 | J43: =SUM(J21:J24)+J29+J31+J33+J35 -> 15269.017 | ... AL43: =SUM(AL21:AL24)+AL29+AL31+AL33+AL35 -> 32276.722
...

Sheet Resultados
A1: Estado de resultados mensual (MXN, sin IVA)
A2: ISR y PTU con pérdidas acumuladas (aproximación). Columnas AM–AO = totales por año del modelo.
A3: Mes # | C3: =Volumen!C3 -> 1 | D3: =Volumen!D3 -> 2 | E3: =Volumen!E3 -> 3 | F3: =Volumen!F3 -> 4 | G3: =Volumen!G3 -> 5 | H3: =Volumen!H3 -> 6 | I3: =Volumen!I3 -> 7 | J3: =Volumen!J3 -> 8 | ... AL3: =Volumen!AL3 -> 36
A4: Fecha | C4: =Volumen!C4 -> 46327 | D4: =Volumen!D4 -> 46357 | E4: =Volumen!E4 -> 46388 | F4: =Volumen!F4 -> 46419 | G4: =Volumen!G4 -> 46447 | H4: =Volumen!H4 -> 46478 | I4: =Volumen!I4 -> 46508 | J4: =Volumen!J4 -> 46539 | ... AL4: =Volumen!AL4 -> 47392 | AM4: Año 1 | AN4: Año 2 | AO4: Año 3
A5: Año del modelo | C5: =Volumen!C6 -> 1 | D5: =Volumen!D6 -> 1 | E5: =Volumen!E6 -> 1 | F5: =Volumen!F6 -> 1 | G5: =Volumen!G6 -> 1 | H5: =Volumen!H6 -> 1 | I5: =Volumen!I6 -> 1 | J5: =Volumen!J6 -> 1 | ... AL5: =Volumen!AL6 -> 3
A7: INGRESOS NETOS (sin IVA)
A8: Distribuidor · Semanal | C8: =Volumen!C21*net_sem -> 32902.113 | D8: =Volumen!D21*net_sem -> 18701.254 | E8: =Volumen!E21*net_sem -> 45215.092 | F8: =Volumen!F21*net_sem -> 65578.679 | G8: =Volumen!G21*net_sem -> 92124.07 | H8: =Volumen!H21*net_sem -> 117942.19 | I8: =Volumen!I21*net_sem -> 133578.52 | J8: =Volumen!J21*net_sem -> 132487.61 | ... AL8: =Volumen!AL21*net_sem -> 241370.85 | AM8: =SUMIF($C$5:$AL$5,1,$C8:$AL8) -> 1194372.3 | AN8: =SUMIF($C$5:$AL$5,2,$C8:$AL8) -> 1933709.6 | AO8: =SUMIF($C$5:$AL$5,3,$C8:$AL8) -> 2127080.6
A9: Distribuidor · Repuesto | C9: =Volumen!C22*net_rep -> 22830.038 | D9: =Volumen!D22*net_rep -> 12976.38 | E9: =Volumen!E22*net_rep -> 35855.699 | F9: =Volumen!F22*net_rep -> 52004.084 | G9: =Volumen!G22*net_rep -> 73054.656 | H9: =Volumen!H22*net_rep -> 93528.5 | I9: =Volumen!I22*net_rep -> 105928.15 | J9: =Volumen!J22*net_rep -> 105063.06 | ... AL9: =Volumen!AL22*net_rep -> 167481.81 | AM9: =SUMIF($C$5:$AL$5,1,$C9:$AL9) -> 922252.01 | AN9: =SUMIF($C$5:$AL$5,2,$C9:$AL9) -> 1465465.9 | AO9: =SUMIF($C$5:$AL$5,3,$C9:$AL9) -> 1612012.4
A10: Distribuidor · Temporada | C10: =Volumen!C23*net_tem -> 46555.371 | D10: =Volumen!D23*net_tem -> 26461.638 | E10: =Volumen!E23*net_tem -> 30846.447 | F10: =Volumen!F23*net_tem -> 44738.807 | G10: =Volumen!G23*net_tem -> 62848.491 | H10: =Volumen!H23*net_tem -> 80462.018 | I10: =Volumen!I23*net_tem -> 91129.366 | J10: =Volumen!J23*net_tem -> 90385.133 | ... AL10: =Volumen!AL23*net_tem -> 341531.54 | AM10: =SUMIF($C$5:$AL$5,1,$C10:$AL10) -> 998801.04 | AN10: =SUMIF($C$5:$AL$5,2,$C10:$AL10) -> 1821663.3 | AO10: =SUMIF($C$5:$AL$5,3,$C10:$AL10) -> 2003829.6
A11: Distribuidor · Personalizada | C11: =Volumen!C24*net_per -> 17726.853 | D11: =Volumen!D24*net_per -> 10075.777 | E11: =Volumen!E24*net_per -> 18270.588 | F11: =Volumen!F24*net_per -> 26499.14 | G11: =Volumen!G24*net_per -> 37225.644 | H11: =Volumen!H24*net_per -> 47658.272 | I11: =Volumen!I24*net_per -> 53976.625 | J11: =Volumen!J24*net_per -> 53535.809 | ... AL11: =Volumen!AL24*net_per -> 130044.7 | AM11: =SUMIF($C$5:$AL$5,1,$C11:$AL11) -> 516443.32 | AN11: =SUMIF($C$5:$AL$5,2,$C11:$AL11) -> 873737.84 | AO11: =SUMIF($C$5:$AL$5,3,$C11:$AL11) -> 961111.62
A12: Parroquias | C12: =Volumen!C29*net_parr -> 0 | D12: =Volumen!D29*net_parr -> 333.14871 | E12: =Volumen!E29*net_parr -> 666.29741 | F12: =Volumen!F29*net_parr -> 999.44612 | G12: =Volumen!G29*net_parr -> 1332.5948 | H12: =Volumen!H29*net_parr -> 1665.7435 | I12: =Volumen!I29*net_parr -> 1998.8922 | J12: =Volumen!J29*net_parr -> 1998.8922 | ... AL12: =Volumen!AL29*net_parr -> 1998.8922 | AM12: =SUMIF($C$5:$AL$5,1,$C12:$AL12) -> 16990.584 | AN12: =SUMIF($C$5:$AL$5,2,$C12:$AL12) -> 23986.707 | AO12: =SUMIF($C$5:$AL$5,3,$C12:$AL12) -> 23986.707
A13: Restaurantes y hoteles | C13: =Volumen!C31*net_rest -> 0 | D13: =Volumen!D31*net_rest -> 0 | E13: =Volumen!E31*net_rest -> 711.54899 | F13: =Volumen!F31*net_rest -> 1423.098 | G13: =Volumen!G31*net_rest -> 2134.647 | H13: =Volumen!H31*net_rest -> 2846.1959 | I13: =Volumen!I31*net_rest -> 3557.7449 | J13: =Volumen!J31*net_rest -> 4269.2939 | ... AL13: =Volumen!AL31*net_rest -> 6403.9409 | AM13: =SUMIF($C$5:$AL$5,1,$C13:$AL13) -> 38423.645 | AN13: =SUMIF($C$5:$AL$5,2,$C13:$AL13) -> 76847.291 | AO13: =SUMIF($C$5:$AL$5,3,$C13:$AL13) -> 76847.291
A14: Recaudación con colegios y parroquias | C14: =Volumen!C33*net_recaud -> 0 | D14: =Volumen!D33*net_recaud -> 17741.379 | E14: =Volumen!E33*net_recaud -> 8870.6897 | F14: =Volumen!F33*net_recaud -> 8870.6897 | G14: =Volumen!G33*net_recaud -> 8870.6897 | H14: =Volumen!H33*net_recaud -> 8870.6897 | I14: =Volumen!I33*net_recaud -> 8870.6897 | J14: =Volumen!J33*net_recaud -> 8870.6897 | ... AL14: =Volumen!AL33*net_recaud -> 17741.379 | AM14: =SUMIF($C$5:$AL$5,1,$C14:$AL14) -> 115318.97 | AN14: =SUMIF($C$5:$AL$5,2,$C14:$AL14) -> 133060.34 | AO14: =SUMIF($C$5:$AL$5,3,$C14:$AL14) -> 133060.34
A15: Regalos corporativos | C15: =Volumen!C35*net_corp -> 128793.1 | D15: =Volumen!D35*net_corp -> 128793.1 | E15: =Volumen!E35*net_corp -> 0 | F15: =Volumen!F35*net_corp -> 0 | G15: =Volumen!G35*net_corp -> 0 | H15: =Volumen!H35*net_corp -> 0 | I15: =Volumen!I35*net_corp -> 0 | J15: =Volumen!J35*net_corp -> 0 | ... AL15: =Volumen!AL35*net_corp -> 0 | AM15: =SUMIF($C$5:$AL$5,1,$C15:$AL15) -> 257586.21 | AN15: =SUMIF($C$5:$AL$5,2,$C15:$AL15) -> 257586.21 | AO15: =SUMIF($C$5:$AL$5,3,$C15:$AL15) -> 257586.21
A16: Vela Récord premium | C16: =Volumen!C36*net_prem -> 0 | D16: =Volumen!D36*net_prem -> 0 | E16: =Volumen!E36*net_prem -> 0 | F16: =Volumen!F36*net_prem -> 23356.681 | G16: =Volumen!G36*net_prem -> 26104.526 | H16: =Volumen!H36*net_prem -> 27478.448 | I16: =Volumen!I36*net_prem -> 26104.526 | J16: =Volumen!J36*net_prem -> 21982.759 | ... AL16: =Volumen!AL36*net_prem -> 43965.517 | AM16: =SUMIF($C$5:$AL$5,1,$C16:$AL16) -> 236314.66 | AN16: =SUMIF($C$5:$AL$5,2,$C16:$AL16) -> 351724.14 | AO16: =SUMIF($C$5:$AL$5,3,$C16:$AL16) -> 351724.14
A17: Recargas Vela Récord | C17: =Volumen!C37*net_recp -> 0 | D17: =Volumen!D37*net_recp -> 0 | E17: =Volumen!E37*net_recp -> 0 | F17: =Volumen!F37*net_recp -> 0 | G17: =Volumen!G37*net_recp -> 0 | H17: =Volumen!H37*net_recp -> 6896.5517 | I17: =Volumen!I37*net_recp -> 6896.5517 | J17: =Volumen!J37*net_recp -> 6896.5517 | ... AL17: =Volumen!AL37*net_recp -> 6896.5517 | AM17: =SUMIF($C$5:$AL$5,1,$C17:$AL17) -> 48275.862 | AN17: =SUMIF($C$5:$AL$5,2,$C17:$AL17) -> 82758.621 | AO17: =SUMIF($C$5:$AL$5,3,$C17:$AL17) -> 82758.621
A18: Insumos en línea | C18: =Volumen!C38*ticket_ins/(1+iva) -> 0 | D18: =Volumen!D38*ticket_ins/(1+iva) -> 8863.1466 | E18: =Volumen!E38*ticket_ins/(1+iva) -> 17726.293 | F18: =Volumen!F38*ticket_ins/(1+iva) -> 26589.44 | G18: =Volumen!G38*ticket_ins/(1+iva) -> 35452.586 | H18: =Volumen!H38*ticket_ins/(1+iva) -> 44315.733 | I18: =Volumen!I38*ticket_ins/(1+iva) -> 53178.879 | J18: =Volumen!J38*ticket_ins/(1+iva) -> 62042.026 | ... AL18: =Volumen!AL38*ticket_ins/(1+iva) -> 70905.172 | AM18: =SUMIF($C$5:$AL$5,1,$C18:$AL18) -> 531788.79 | AN18: =SUMIF($C$5:$AL$5,2,$C18:$AL18) -> 850862.07 | AO18: =SUMIF($C$5:$AL$5,3,$C18:$AL18) -> 850862.07
A19: Talleres | C19: =Volumen!C40*p_taller/(1+iva) -> 0 | D19: =Volumen!D40*p_taller/(1+iva) -> 31034.483 | E19: =Volumen!E40*p_taller/(1+iva) -> 31034.483 | F19: =Volumen!F40*p_taller/(1+iva) -> 31034.483 | G19: =Volumen!G40*p_taller/(1+iva) -> 31034.483 | H19: =Volumen!H40*p_taller/(1+iva) -> 31034.483 | I19: =Volumen!I40*p_taller/(1+iva) -> 31034.483 | J19: =Volumen!J40*p_taller/(1+iva) -> 31034.483 | ... AL19: =Volumen!AL40*p_taller/(1+iva) -> 31034.483 | AM19: =SUMIF($C$5:$AL$5,1,$C19:$AL19) -> 341379.31 | AN19: =SUMIF($C$5:$AL$5,2,$C19:$AL19) -> 372413.79 | AO19: =SUMIF($C$5:$AL$5,3,$C19:$AL19) -> 372413.79
A20: TOTAL INGRESOS | C20: =SUM(C8:C19) -> 248807.48 | D20: =SUM(D8:D19) -> 254980.31 | E20: =SUM(E8:E19) -> 189197.14 | F20: =SUM(F8:F19) -> 281094.55 | G20: =SUM(G8:G19) -> 370182.39 | H20: =SUM(H8:H19) -> 462698.82 | I20: =SUM(I8:I19) -> 516254.42 | J20: =SUM(J8:J19) -> 518566.31 | ... AL20: =SUM(AL8:AL19) -> 1059374.8 | AM20: =SUMIF($C$5:$AL$5,1,$C20:$AL20) -> 5217946.7 | AN20: =SUMIF($C$5:$AL$5,2,$C20:$AL20) -> 8243815.7 | AO20: =SUMIF($C$5:$AL$5,3,$C20:$AL20) -> 8853273.4
A22: COSTO DE VENTAS
A23: Materiales canal distribuidor | C23: =Volumen!C21*mat_sem+Volumen!C22*mat_rep+Volumen!C23*mat_tem+Volumen!C24*mat_per -> 74170.451 | D23: =Volumen!D21*mat_sem+Volumen!D22*mat_rep+Volumen!D23*mat_tem+Volumen!D24*mat_per -> 42157.791 | E23: =Volumen!E21*mat_sem+Volumen!E22*mat_rep+Volumen!E23*mat_tem+Volumen!E24*mat_per -> 83806.198 | F23: =Volumen!F21*mat_sem+Volumen!F22*mat_rep+Volumen!F23*mat_tem+Volumen!F24*mat_per -> 121550.12 | G23: =Volumen!G21*mat_sem+Volumen!G22*mat_rep+Volumen!G23*mat_tem+Volumen!G24*mat_per -> 170752.01 | H23: =Volumen!H21*mat_sem+Volumen!H22*mat_rep+Volumen!H23*mat_tem+Volumen!H24*mat_per -> 218605.91 | I23: =Volumen!I21*mat_sem+Volumen!I22*mat_rep+Volumen!I23*mat_tem+Volumen!I24*mat_per -> 247587.85 | J23: =Volumen!J21*mat_sem+Volumen!J22*mat_rep+Volumen!J23*mat_tem+Volumen!J24*mat_per -> 245565.86 | ... AL23: =Volumen!AL21*mat_sem+Volumen!AL22*mat_rep+Volumen!AL23*mat_tem+Volumen!AL24*mat_per -> 544116.55 | AM23: =SUMIF($C$5:$AL$5,1,$C23:$AL23) -> 2314397.9 | AN23: =SUMIF($C$5:$AL$5,2,$C23:$AL23) -> 3858948.8 | AO23: =SUMIF($C$5:$AL$5,3,$C23:$AL23) -> 4244843.7
A24: Transformación canal distribuidor (maquila o planta) | C24: =(Volumen!C21+Volumen!C23+Volumen!C24+Volumen!C22*factor_transf_rep)*IF(C$3>=mes_planta,transf_propia,transf_maquila) -> 8720.2294 | D24: =(Volumen!D21+Volumen!D23+Volumen!D24+Volumen!D22*factor_transf_rep)*IF(D$3>=mes_planta,transf_propia,transf_maquila) -> 4956.4969 | E24: =(Volumen!E21+Volumen!E23+Volumen!E24+Volumen!E22*factor_transf_rep)*IF(E$3>=mes_planta,transf_propia,transf_maquila) -> 9994.05 | F24: =(Volumen!F21+Volumen!F23+Volumen!F24+Volumen!F22*factor_transf_rep)*IF(F$3>=mes_planta,transf_propia,transf_maquila) -> 14495.085 | G24: =(Volumen!G21+Volumen!G23+Volumen!G24+Volumen!G22*factor_transf_rep)*IF(G$3>=mes_planta,transf_propia,transf_maquila) -> 20362.506 | H24: =(Volumen!H21+Volumen!H23+Volumen!H24+Volumen!H22*factor_transf_rep)*IF(H$3>=mes_planta,transf_propia,transf_maquila) -> 26069.175 | I24: =(Volumen!I21+Volumen!I23+Volumen!I24+Volumen!I22*factor_transf_rep)*IF(I$3>=mes_planta,transf_propia,transf_maquila) -> 29525.327 | J24: =(Volumen!J21+Volumen!J23+Volumen!J24+Volumen!J22*factor_transf_rep)*IF(J$3>=mes_planta,transf_propia,transf_maquila) -> 29284.2 | ... AL24: =(Volumen!AL21+Volumen!AL23+Volumen!AL24+Volumen!AL22*factor_transf_rep)*IF(AL$3>=mes_planta,transf_propia,transf_maquila) -> 63971.853 | AM24: =SUMIF($C$5:$AL$5,1,$C24:$AL24) -> 275044.48 | AN24: =SUMIF($C$5:$AL$5,2,$C24:$AL24) -> 457587.36 | AO24: =SUMIF($C$5:$AL$5,3,$C24:$AL24) -> 503346.1
A25: Parroquias y restaurantes (repuesto) | C25: =(Volumen!C29+Volumen!C31)*(mat_rep+factor_transf_rep*IF(C$3>=mes_planta,transf_propia,transf_maquila)) -> 0 | D25: =(Volumen!D29+Volumen!D31)*(mat_rep+factor_transf_rep*IF(D$3>=mes_planta,transf_propia,transf_maquila)) -> 135.94629 | E25: =(Volumen!E29+Volumen!E31)*(mat_rep+factor_transf_rep*IF(E$3>=mes_planta,transf_propia,transf_maquila)) -> 576.76863 | F25: =(Volumen!F29+Volumen!F31)*(mat_rep+factor_transf_rep*IF(F$3>=mes_planta,transf_propia,transf_maquila)) -> 1017.591 | G25: =(Volumen!G29+Volumen!G31)*(mat_rep+factor_transf_rep*IF(G$3>=mes_planta,transf_propia,transf_maquila)) -> 1458.4133 | H25: =(Volumen!H29+Volumen!H31)*(mat_rep+factor_transf_rep*IF(H$3>=mes_planta,transf_propia,transf_maquila)) -> 1899.2357 | I25: =(Volumen!I29+Volumen!I31)*(mat_rep+factor_transf_rep*IF(I$3>=mes_planta,transf_propia,transf_maquila)) -> 2340.058 | J25: =(Volumen!J29+Volumen!J31)*(mat_rep+factor_transf_rep*IF(J$3>=mes_planta,transf_propia,transf_maquila)) -> 2644.9341 | ... AL25: =(Volumen!AL29+Volumen!AL31)*(mat_rep+factor_transf_rep*IF(AL$3>=mes_planta,transf_propia,transf_maquila)) -> 3559.5623 | AM25: =SUMIF($C$5:$AL$5,1,$C25:$AL25) -> 23396.568 | AN25: =SUMIF($C$5:$AL$5,2,$C25:$AL25) -> 42714.747 | AO25: =SUMIF($C$5:$AL$5,3,$C25:$AL25) -> 42714.747
